Workbook

Sheet Sales
A1: OrderID | B1: OrderDate | C1: Region | D1: Product | E1: Salesperson | F1: Units | G1: MRP | H1: DiscountPct | I1: CustomerID | J1: Rating | K1: PaymentMode | L1: Category | M1: NetSales | N1: City | O1: Segment | P1: Month
A2: ORD1001 | B2: 45760 | C2: North | D2: Wall Clock | E2: Aman Verma | F2: 1 | G2: 349 | H2: 15 | I2: C036 | J2: 3 | K2: UPI | L2: =VLOOKUP(D2,Products!$A$2:$D$13,2,FALSE()) -> Home | M2: =F2*G2*(1-H2/100) -> 296.65 | N2: =VLOOKUP(I2,Customers!$A$2:$D$121,3,FALSE()) -> Mumbai | O2: =VLOOKUP(I2,Customers!$A$2:$D$121,4,FALSE()) -> Student | P2: =TEXT(B2,"yyyy-mm") -> 2025-04
A3: ORD1002 | B3: 45792 | C3: Central | D3: Wall Clock | E3: Vikas Joshi | F3: 6 | G3: 349 | H3: 10 | I3: C055 | J3: 1 | K3: Card | L3: =VLOOKUP(D3,Products!$A$2:$D$13,2,FALSE()) -> Home | M3: =F3*G3*(1-H3/100) -> 1884.6 | N3: =VLOOKUP(I3,Customers!$A$2:$D$121,3,FALSE()) -> Indore | O3: =VLOOKUP(I3,Customers!$A$2:$D$121,4,FALSE()) -> Corporate | P3: =TEXT(B3,"yyyy-mm") -> 2025-05
A4: ORD1003 | B4: 46056 | C4: Central | D4: Wireless Mouse | E4: Neha Tiwari | F4: 3 | G4: 450 | H4: 0 | I4: C072 | J4: 3 | K4: Card | L4: =VLOOKUP(D4,Products!$A$2:$D$13,2,FALSE()) -> Electronics | M4: =F4*G4*(1-H4/100) -> 1350 | N4: =VLOOKUP(I4,Customers!$A$2:$D$121,3,FALSE()) -> Chennai | O4: =VLOOKUP(I4,Customers!$A$2:$D$121,4,FALSE()) -> Student | P4: =TEXT(B4,"yyyy-mm") -> 2026-02
A5: ORD1004 | B5: 45890 | C5: Central | D5: Water Bottle | E5: Neha Tiwari | F5: 2 | G5: 249 | H5: 0 | I5: C098 | J5: 5 | K5: Cash | L5: =VLOOKUP(D5,Products!$A$2:$D$13,2,FALSE()) -> Accessories | M5: =F5*G5*(1-H5/100) -> 498 | N5: =VLOOKUP(I5,Customers!$A$2:$D$121,3,FALSE()) -> Indore | O5: =VLOOKUP(I5,Customers!$A$2:$D$121,4,FALSE()) -> Corporate | P5: =TEXT(B5,"yyyy-mm") -> 2025-08
A6: ORD1005 | B6: 45858 | C6: South | D6: USB Flash 64GB | E6: Kiran Rao | F6: 1 | G6: 500 | H6: 0 | I6: C014 | J6: 2 | K6: Cash | L6: =VLOOKUP(D6,Products!$A$2:$D$13,2,FALSE()) -> Electronics | M6: =F6*G6*(1-H6/100) -> 500 | N6: =VLOOKUP(I6,Customers!$A$2:$D$121,3,FALSE()) -> Chennai | O6: =VLOOKUP(I6,Customers!$A$2:$D$121,4,FALSE()) -> Retail | P6: =TEXT(B6,"yyyy-mm") -> 2025-07
A7: ORD1006 | B7: 45883 | C7: Central | D7: Earphones | E7: Vikas Joshi | F7: 1 | G7: 399 | H7: 0 | I7: C094 | J7: 4 | K7: Net Banking | L7: =VLOOKUP(D7,Products!$A$2:$D$13,2,FALSE()) -> Electronics | M7: =F7*G7*(1-H7/100) -> 399 | N7: =VLOOKUP(I7,Customers!$A$2:$D$121,3,FALSE()) -> Indore | O7: =VLOOKUP(I7,Customers!$A$2:$D$121,4,FALSE()) -> Retail | P7: =TEXT(B7,"yyyy-mm") -> 2025-08
A8: ORD1007 | B8: 45898 | C8: Central | D8: Gel Pen Pack | E8: Neha Tiwari | F8: 1 | G8: 30 | H8: 15 | I8: C080 | J8: 5 | K8: Card | L8: =VLOOKUP(D8,Products!$A$2:$D$13,2,FALSE()) -> Stationery | M8: =F8*G8*(1-H8/100) -> 25.5 | N8: =VLOOKUP(I8,Customers!$A$2:$D$121,3,FALSE()) -> Indore | O8: =VLOOKUP(I8,Customers!$A$2:$D$121,4,FALSE()) -> Student | P8: =TEXT(B8,"yyyy-mm") -> 2025-08
A9: ORD1008 | B9: 45771 | C9: North | D9: Photo Frame | E9: Aman Verma | F9: 4 | G9: 199 | H9: 15 | I9: C030 | J9: 5 | K9: Card | L9: =VLOOKUP(D9,Products!$A$2:$D$13,2,FALSE()) -> Home | M9: =F9*G9*(1-H9/100) -> 676.6 | N9: =VLOOKUP(I9,Customers!$A$2:$D$121,3,FALSE()) -> Indore | O9: =VLOOKUP(I9,Customers!$A$2:$D$121,4,FALSE()) -> Student | P9: =TEXT(B9,"yyyy-mm") -> 2025-04
A10: ORD1009 | B10: 45890 | C10: West | D10: Gel Pen Pack | E10: Rahul Mehta | F10: 2 | G10: 30 | H10: 5 | I10: C082 | J10: 5 | K10: Cash | L10: =VLOOKUP(D10,Products!$A$2:$D$13,2,FALSE()) -> Stationery | M10: =F10*G10*(1-H10/100) -> 57 | N10: =VLOOKUP(I10,Customers!$A$2:$D$121,3,FALSE()) -> Nagpur | O10: =VLOOKUP(I10,Customers!$A$2:$D$121,4,FALSE()) -> Retail | P10: =TEXT(B10,"yyyy-mm") -> 2025-08
A11: ORD1010 | B11: 46091 | C11: South | D11: Earphones | E11: Kiran Rao | F11: 3 | G11: 399 | H11: 0 | I11: C090 | J11: 5 | K11: Card | L11: =VLOOKUP(D11,Products!$A$2:$D$13,2,FALSE()) -> Electronics | M11: =F11*G11*(1-H11/100) -> 1197 | N11: =VLOOKUP(I11,Customers!$A$2:$D$121,3,FALSE()) -> Jaipur | O11: =VLOOKUP(I11,Customers!$A$2:$D$121,4,FALSE()) -> Corporate | P11: =TEXT(B11,"yyyy-mm") -> 2026-03
A12: ORD1011 | B12: 45831 | C12: South | D12: Laptop Sleeve | E12: Kiran Rao | F12: 1 | G12: 549 | H12: 5 | I12: C049 | J12: 3 | K12: Cash | L12: =VLOOKUP(D12,Products!$A$2:$D$13,2,FALSE()) -> Accessories | M12: =F12*G12*(1-H12/100) -> 521.55 | N12: =VLOOKUP(I12,Customers!$A$2:$D$121,3,FALSE()) -> Kolkata | O12: =VLOOKUP(I12,Customers!$A$2:$D$121,4,FALSE()) -> Corporate | P12: =TEXT(B12,"yyyy-mm") -> 2025-06
A13: ORD1012 | B13: 45764 | C13: South | D13: Notebook A5 | E13: Kiran Rao | F13: 6 | G13: 40 | H13: 0 | I13: C052 | J13: 3 | K13: Cash | L13: =VLOOKUP(D13,Products!$A$2:$D$13,2,FALSE()) -> Stationery | M13: =F13*G13*(1-H13/100) -> 240 | N13: =VLOOKUP(I13,Customers!$A$2:$D$121,3,FALSE()) -> Delhi | O13: =VLOOKUP(I13,Customers!$A$2:$D$121,4,FALSE()) -> Retail | P13: =TEXT(B13,"yyyy-mm") -> 2025-04
... A259: ORD1263 | B259: 45803 | C259: North | D259: Laptop Sleeve | E259: Riya Singh | F259: 1 | G259: 549 | H259: 5 | I259: C018 | J259: 5 | K259: Net Banking | L259: =VLOOKUP(D259,Products!$A$2:$D$13,2,FALSE()) -> Accessories | M259: =F259*G259*(1-H259/100) -> 521.55 | N259: =VLOOKUP(I259,Customers!$A$2:$D$121,3,FALSE()) -> Pune | O259: =VLOOKUP(I259,Customers!$A$2:$D$121,4,FALSE()) -> Retail | P259: =TEXT(B259,"yyyy-mm") -> 2025-05
A260: ORD1264 | B260: 45953 | C260: North | D260: Earphones | E260: Riya Singh | F260: 2 | G260: 399 | H260: 0 | I260: C073 | J260: N/A | K260: Cash | L260: =VLOOKUP(D260,Products!$A$2:$D$13,2,FALSE()) -> Electronics | M260: =F260*G260*(1-H260/100) -> 798 | N260: =VLOOKUP(I260,Customers!$A$2:$D$121,3,FALSE()) -> Jaipur | O260: =VLOOKUP(I260,Customers!$A$2:$D$121,4,FALSE()) -> Retail | P260: =TEXT(B260,"yyyy-mm") -> 2025-10
A261: ORD1265 | B261: 46006 | C261: West | D261: Gel Pen Pack | E261: Rahul Mehta | F261: 4 | G261: 30 | H261: 5 | I261: C098 | J261: 4 | K261: Card | L261: =VLOOKUP(D261,Products!$A$2:$D$13,2,FALSE()) -> Stationery | M261: =F261*G261*(1-H261/100) -> 114 | N261: =VLOOKUP(I261,Customers!$A$2:$D$121,3,FALSE()) -> Indore | O261: =VLOOKUP(I261,Customers!$A$2:$D$121,4,FALSE()) -> Corporate | P261: =TEXT(B261,"yyyy-mm") -> 2025-12
A262: ORD1266 | B262: 45939 | C262: West | D262: Gel Pen Pack | E262: Rahul Mehta | F262: 3 | G262: 30 | H262: 0 | I262: C072 | J262: 5 | K262: Card | L262: =VLOOKUP(D262,Products!$A$2:$D$13,2,FALSE()) -> Stationery | M262: =F262*G262*(1-H262/100) -> 90 | N262: =VLOOKUP(I262,Customers!$A$2:$D$121,3,FALSE()) -> Chennai | O262: =VLOOKUP(I262,Customers!$A$2:$D$121,4,FALSE()) -> Student | P262: =TEXT(B262,"yyyy-mm") -> 2025-10
A263: ORD1267 | B263: 45953 | C263: Central | D263: Study Lamp | E263: Vikas Joshi | F263: 2 | G263: 699 | H263: 10 | I263: C006 | J263: 1 | K263: Cash | L263: =VLOOKUP(D263,Products!$A$2:$D$13,2,FALSE()) -> Home | M263: =F263*G263*(1-H263/100) -> 1258.2 | N263: =VLOOKUP(I263,Customers!$A$2:$D$121,3,FALSE()) -> Mumbai | O263: =VLOOKUP(I263,Customers!$A$2:$D$121,4,FALSE()) -> Retail | P263: =TEXT(B263,"yyyy-mm") -> 2025-10
A264: ORD1268 | B264: 45981 | C264: Central | D264: Water Bottle | E264: Vikas Joshi | F264: 3 | G264: 249 | H264: 0 | I264: C078 | J264: 5 | K264: Cash | L264: =VLOOKUP(D264,Products!$A$2:$D$13,2,FALSE()) -> Accessories | M264: =F264*G264*(1-H264/100) -> 747 | N264: =VLOOKUP(I264,Customers!$A$2:$D$121,3,FALSE()) -> Indore | O264: =VLOOKUP(I264,Customers!$A$2:$D$121,4,FALSE()) -> Corporate | P264: =TEXT(B264,"yyyy-mm") -> 2025-11
A265: ORD1269 | B265: 45831 | C265: East | D265: Study Lamp | E265: Tanya Ghosh | F265: 1 | G265: 699 | H265: 5 | I265: C079 | J265: 5 | K265: Cash | L265: =VLOOKUP(D265,Products!$A$2:$D$13,2,FALSE()) -> Home | M265: =F265*G265*(1-H265/100) -> 664.05 | N265: =VLOOKUP(I265,Customers!$A$2:$D$121,3,FALSE()) -> Bhopal | O265: =VLOOKUP(I265,Customers!$A$2:$D$121,4,FALSE()) -> Student | P265: =TEXT(B265,"yyyy-mm") -> 2025-06
A266: ORD1270 | B266: 46020 | C266: Central | D266: Laptop Sleeve | E266: Neha Tiwari | F266: 1 | G266: 549 | H266: 5 | I266: C091 | J266: 4 | K266: UPI | L266: =VLOOKUP(D266,Products!$A$2:$D$13,2,FALSE()) -> Accessories | M266: =F266*G266*(1-H266/100) -> 521.55 | N266: =VLOOKUP(I266,Customers!$A$2:$D$121,3,FALSE()) -> Delhi | O266: =VLOOKUP(I266,Customers!$A$2:$D$121,4,FALSE()) -> Student | P266: =TEXT(B266,"yyyy-mm") -> 2025-12
A267: ORD1271 | B267: 46092 | C267: East | D267: Earphones | E267: Sourav Das | F267: 3 | G267: 399 | H267: 0 | I267: C054 | J267: 4 | K267: Net Banking | L267: =VLOOKUP(D267,Products!$A$2:$D$13,2,FALSE()) -> Electronics | M267: =F267*G267*(1-H267/100) -> 1197 | N267: =VLOOKUP(I267,Customers!$A$2:$D$121,3,FALSE()) -> Kolkata | O267: =VLOOKUP(I267,Customers!$A$2:$D$121,4,FALSE()) -> Retail | P267: =TEXT(B267,"yyyy-mm") -> 2026-03
A268: ORD1272 | B268: 46043 | C268: Central | D268: USB Flash 64GB | E268: Neha Tiwari | F268: 3 | G268: 500 | H268: 0 | I268: C093 | J268: 2 | K268: Card | L268: =VLOOKUP(D268,Products!$A$2:$D$13,2,FALSE()) -> Electronics | M268: =F268*G268*(1-H268/100) -> 1500 | N268: =VLOOKUP(I268,Customers!$A$2:$D$121,3,FALSE()) -> Jaipur | O268: =VLOOKUP(I268,Customers!$A$2:$D$121,4,FALSE()) -> Retail | P268: =TEXT(B268,"yyyy-mm") -> 2026-01
A269: ORD1273 | B269: 45942 | C269: Central | D269: Laptop Sleeve | E269: Vikas Joshi | F269: 4 | G269: 549 | H269: 0 | I269: C106 | J269: 4 | K269: UPI | L269: =VLOOKUP(D269,Products!$A$2:$D$13,2,FALSE()) -> Accessories | M269: =F269*G269*(1-H269/100) -> 2196 | N269: =VLOOKUP(I269,Customers!$A$2:$D$121,3,FALSE()) -> Bhopal | O269: =VLOOKUP(I269,Customers!$A$2:$D$121,4,FALSE()) -> Corporate | P269: =TEXT(B269,"yyyy-mm") -> 2025-10
A270: ORD1274 | B270: 45973 | C270: North | D270: Wireless Mouse | E270: Aman Verma | F270: 5 | G270: 450 | H270: 0 | I270: C054 | J270: 3 | K270: Net Banking | L270: =VLOOKUP(D270,Products!$A$2:$D$13,2,FALSE()) -> Electronics | M270: =F270*G270*(1-H270/100) -> 2250 | N270: =VLOOKUP(I270,Customers!$A$2:$D$121,3,FALSE()) -> Kolkata | O270: =VLOOKUP(I270,Customers!$A$2:$D$121,4,FALSE()) -> Retail | P270: =TEXT(B270,"yyyy-mm") -> 2025-11
A271: ORD1275 | B271: 45989 | C271: Central | D271: Laptop Sleeve | E271: Vikas Joshi | F271: 2 | G271: 549 | H271: 15 | I271: C094 | J271: 2 | K271: Card | L271: =VLOOKUP(D271,Products!$A$2:$D$13,2,FALSE()) -> Accessories | M271: =F271*G271*(1-H271/100) -> 933.3 | N271: =VLOOKUP(I271,Customers!$A$2:$D$121,3,FALSE()) -> Indore | O271: =VLOOKUP(I271,Customers!$A$2:$D$121,4,FALSE()) -> Retail | P271: =TEXT(B271,"yyyy-mm") -> 2025-11
A272: ORD1276 | B272: 46087 | C272: East | D272: Laptop Sleeve | E272: Sourav Das | F272: 2 | G272: 549 | H272: 5 | I272: C068 | J272: 4 | K272: Net Banking | L272: =VLOOKUP(D272,Products!$A$2:$D$13,2,FALSE()) -> Accessories | M272: =F272*G272*(1-H272/100) -> 1043.1 | N272: =VLOOKUP(I272,Customers!$A$2:$D$121,3,FALSE()) -> Mumbai | O272: =VLOOKUP(I272,Customers!$A$2:$D$121,4,FALSE()) -> Retail | P272: =TEXT(B272,"yyyy-mm") -> 2026-03
... A778: ORD1789 | B778: 45757 | C778: Central | D778: Laptop Sleeve | E778: Neha Tiwari | F778: 2 | G778: 549 | H778: 0 | I778: C074 | J778: 4 | K778: UPI | L778: =VLOOKUP(D778,Products!$A$2:$D$13,2,FALSE()) -> Accessories | M778: =F778*G778*(1-H778/100) -> 1098 | N778: =VLOOKUP(I778,Customers!$A$2:$D$121,3,FALSE()) -> Pune | O778: =VLOOKUP(I778,Customers!$A$2:$D$121,4,FALSE()) -> Student | P778: =TEXT(B778,"yyyy-mm") -> 2025-04
A779: ORD1790 | B779: 45763 | C779: East | D779: Desk Organizer | E779: Sourav Das | F779: 5 | G779: 180 | H779: 0 | I779: C049 | J779: N/A | K779: Net Banking | L779: =VLOOKUP(D779,Products!$A$2:$D$13,2,FALSE()) -> Stationery | M779: =F779*G779*(1-H779/100) -> 900 | N779: =VLOOKUP(I779,Customers!$A$2:$D$121,3,FALSE()) -> Kolkata | O779: =VLOOKUP(I779,Customers!$A$2:$D$121,4,FALSE()) -> Corporate | P779: =TEXT(B779,"yyyy-mm") -> 2025-04
A780: ORD1791 | B780: 45807 | C780: Central | D780: Desk Organizer | E780: Vikas Joshi | F780: 1 | G780: 180 | H780: 0 | I780: C091 | J780: 5 | K780: Cash | L780: =VLOOKUP(D780,Products!$A$2:$D$13,2,FALSE()) -> Stationery | M780: =F780*G780*(1-H780/100) -> 180 | N780: =VLOOKUP(I780,Customers!$A$2:$D$121,3,FALSE()) -> Delhi | O780: =VLOOKUP(I780,Customers!$A$2:$D$121,4,FALSE()) -> Student | P780: =TEXT(B780,"yyyy-mm") -> 2025-05
A781: ORD1792 | B781: 46002 | C781: North | D781: Backpack | E781: Riya Singh | F781: 2 | G781: 799 | H781: 0 | I781: C048 | J781: 4 | K781: Card | L781: =VLOOKUP(D781,Products!$A$2:$D$13,2,FALSE()) -> Accessories | M781: =F781*G781*(1-H781/100) -> 1598 | N781: =VLOOKUP(I781,Customers!$A$2:$D$121,3,FALSE()) -> Jaipur | O781: =VLOOKUP(I781,Customers!$A$2:$D$121,4,FALSE()) -> Student | P781: =TEXT(B781,"yyyy-mm") -> 2025-12
A782: ORD1793 | B782: 45837 | C782: East | D782: Laptop Sleeve | E782: Sourav Das | F782: 2 | G782: 549 | H782: 0 | I782: C048 | J782: 5 | K782: UPI | L782: =VLOOKUP(D782,Products!$A$2:$D$13,2,FALSE()) -> Accessories | M782: =F782*G782*(1-H782/100) -> 1098 | N782: =VLOOKUP(I782,Customers!$A$2:$D$121,3,FALSE()) -> Jaipur | O782: =VLOOKUP(I782,Customers!$A$2:$D$121,4,FALSE()) -> Student | P782: =TEXT(B782,"yyyy-mm") -> 2025-06
A783: ORD1794 | B783: 45760 | C783: Central | D783: Water Bottle | E783: Vikas Joshi | F783: 2 | G783: 249 | H783: 5 | I783: C116 | J783: 4 | K783: Cash | L783: =VLOOKUP(D783,Products!$A$2:$D$13,2,FALSE()) -> Accessories | M783: =F783*G783*(1-H783/100) -> 473.1 | N783: =VLOOKUP(I783,Customers!$A$2:$D$121,3,FALSE()) -> Chennai | O783: =VLOOKUP(I783,Customers!$A$2:$D$121,4,FALSE()) -> Corporate | P783: =TEXT(B783,"yyyy-mm") -> 2025-04
A784: ORD1795 | B784: 45906 | C784: Central | D784: Water Bottle | E784: Vikas Joshi | F784: 1 | G784: 249 | H784: 0 | I784: C019 | J784: 5 | K784: Card | L784: =VLOOKUP(D784,Products!$A$2:$D$13,2,FALSE()) -> Accessories | M784: =F784*G784*(1-H784/100) -> 249 | N784: =VLOOKUP(I784,Customers!$A$2:$D$121,3,FALSE()) -> Kolkata | O784: =VLOOKUP(I784,Customers!$A$2:$D$121,4,FALSE()) -> Student | P784: =TEXT(B784,"yyyy-mm") -> 2025-09
A785: ORD1796 | B785: 45983 | C785: North | D785: Wireless Mouse | E785: Aman Verma | F785: 4 | G785: 450 | H785: 5 | I785: C092 | J785: 5 | K785: UPI | L785: =VLOOKUP(D785,Products!$A$2:$D$13,2,FALSE()) -> Electronics | M785: =F785*G785*(1-H785/100) -> 1710 | N785: =VLOOKUP(I785,Customers!$A$2:$D$121,3,FALSE()) -> Mumbai | O785: =VLOOKUP(I785,Customers!$A$2:$D$121,4,FALSE()) -> Student | P785: =TEXT(B785,"yyyy-mm") -> 2025-11
A786: ORD1797 | B786: 46099 | C786: North | D786: USB Flash 64GB | E786: Riya Singh | F786: 5 | G786: 500 | H786: 10 | I786: C112 | J786: 2 | K786: UPI | L786: =VLOOKUP(D786,Products!$A$2:$D$13,2,FALSE()) -> Electronics | M786: =F786*G786*(1-H786/100) -> 2250 | N786: =VLOOKUP(I786,Customers!$A$2:$D$121,3,FALSE()) -> Kolkata | O786: =VLOOKUP(I786,Customers!$A$2:$D$121,4,FALSE()) -> Student | P786: =TEXT(B786,"yyyy-mm") -> 2026-03
A787: ORD1798 | B787: 46085 | C787: Central | D787: Gel Pen Pack | E787: Neha Tiwari | F787: 2 | G787: 30 | H787: 15 | I787: C040 | J787: 1 | K787: Card | L787: =VLOOKUP(D787,Products!$A$2:$D$13,2,FALSE()) -> Stationery | M787: =F787*G787*(1-H787/100) -> 51 | N787: =VLOOKUP(I787,Customers!$A$2:$D$121,3,FALSE()) -> Nagpur | O787: =VLOOKUP(I787,Customers!$A$2:$D$121,4,FALSE()) -> Student | P787: =TEXT(B787,"yyyy-mm") -> 2026-03
A788: ORD1799 | B788: 45846 | C788: South | D788: Earphones | E788: Meena Nair | F788: 2 | G788: 399 | H788: 0 | I788: C036 | J788: 4 | K788: UPI | L788: =VLOOKUP(D788,Products!$A$2:$D$13,2,FALSE()) -> Electronics | M788: =F788*G788*(1-H788/100) -> 798 | N788: =VLOOKUP(I788,Customers!$A$2:$D$121,3,FALSE()) -> Mumbai | O788: =VLOOKUP(I788,Customers!$A$2:$D$121,4,FALSE()) -> Student | P788: =TEXT(B788,"yyyy-mm") -> 2025-07
A789: ORD1800 | B789: 45828 | C789: South | D789: USB Flash 64GB | E789: Kiran Rao | F789: 5 | G789: 500 | H789: 0 | I789: C015 | J789: 1 | K789: Card | L789: =VLOOKUP(D789,Products!$A$2:$D$13,2,FALSE()) -> Electronics | M789: =F789*G789*(1-H789/100) -> 2500 | N789: =VLOOKUP(I789,Customers!$A$2:$D$121,3,FALSE()) -> Chennai | O789: =VLOOKUP(I789,Customers!$A$2:$D$121,4,FALSE()) -> Student | P789: =TEXT(B789,"yyyy-mm") -> 2025-06
A790: ORD1801 | B790: 46029 | C790: East | D790: Laptop Sleeve | E790: Tanya Ghosh | F790: 3 | G790: 549 | H790: 0 | I790: C035 | J790: 3 | K790: Card | L790: =VLOOKUP(D790,Products!$A$2:$D$13,2,FALSE()) -> Accessories | M790: =F790*G790*(1-H790/100) -> 1647 | N790: =VLOOKUP(I790,Customers!$A$2:$D$121,3,FALSE()) -> Pune | O790: =VLOOKUP(I790,Customers!$A$2:$D$121,4,FALSE()) -> Student | P790: =TEXT(B790,"yyyy-mm") -> 2026-01
...

Sheet Products
A1: Product | B1: Category | C1: CostPrice | D1: MRP
A2: Notebook A5 | B2: Stationery | C2: 18 | D2: 40
A3: Gel Pen Pack | B3: Stationery | C3: 12 | D3: 30
A4: Desk Organizer | B4: Stationery | C4: 90 | D4: 180
A5: Wireless Mouse | B5: Electronics | C5: 220 | D5: 450
A6: USB Flash 64GB | B6: Electronics | C6: 260 | D6: 500
A7: Earphones | B7: Electronics | C7: 180 | D7: 399
A8: Backpack | B8: Accessories | C8: 350 | D8: 799
A9: Water Bottle | B9: Accessories | C9: 110 | D9: 249
A10: Laptop Sleeve | B10: Accessories | C10: 240 | D10: 549
A11: Study Lamp | B11: Home | C11: 300 | D11: 699
A12: Wall Clock | B12: Home | C12: 150 | D12: 349
A13: Photo Frame | B13: Home | C13: 80 | D13: 199

Sheet Customers
A1: CustomerID | B1: CustomerName | C1: City | D1: Segment
A2: C001 | B2: Saanvi Jain | C2: Nagpur | D2: Retail
A3: C002 | B3: Isha Mishra | C3: Indore | D3: Student
A4: C003 | B4: Yash Mishra | C4: Delhi | D4: Retail
A5: C004 | B5: Karan Jain | C5: Mumbai | D5: Corporate
A6: C005 | B6: Saanvi Gupta | C6: Bhopal | D6: Student
A7: C006 | B7: Harsh Khan | C7: Mumbai | D7: Retail
A8: C007 | B8: Aarav Mishra | C8: Nagpur | D8: Retail
A9: C008 | B9: Dev Reddy | C9: Kolkata | D9: Student
A10: C009 | B10: Arjun Reddy | C10: Lucknow | D10: Student
A11: C010 | B11: Ananya Khan | C11: Bhopal | D11: Retail
A12: C011 | B12: Kavya Reddy | C12: Bhopal | D12: Retail
... A121: C120 | B121: Pari Patel | C121: Jaipur | D121: Retail
